Workbook

Sheet ahri nyoret nyoret bntr 💰BUDGE
B1: =CONCATENATE('🏦COVER🏦'!D7," 💰Budget Plan💰") -> #REF!
B2: 💔Pessimistic Plan💔 | G2: 🤍Realistic Plan🤍 | L2: 💗Optimistic Plan💗
B3: REVENUE BREAKDOWN | G3: REVENUE BREAKDOWN | L3: REVENUE BREAKDOWN
B4: (revenue stream) | C4: P | D4: Q | E4: Total | G4: (revenue stream) | H4: P | I4: Q | J4: Total | L4: (revenue stream) | M4: P | N4: Q | O4: Total
B5: Delegates Fee | C5: 1150000 | D5: 320 | E5: =C5*D5 -> 368000000 | G5: Delegates Fee | H5: 1150000 | I5: 320 | J5: =H5*I5 -> 368000000 | L5: Delegates Fee | M5: 1150000 | N5: 320 | O5: =M5*N5 -> 368000000
B6: Commitment Fee | C6: 50000 | D6: 320 | E6: =C6*D6 -> 16000000 | G6: Commitment Fee | H6: 50000 | I6: 320 | J6: =H6*I6 -> 16000000 | L6: Commitment Fee | M6: 50000 | N6: 320 | O6: =M6*N6 -> 16000000
B7: Working Capital from MC | C7: 40000000 | D7: 1 | E7: =C7*D7 -> 40000000 | G7: Working Capital from MC | H7: 40000000 | I7: 1 | J7: =H7*I7 -> 40000000 | L7: Working Capital from MC | M7: 40000000 | N7: 1 | O7: =M7*N7 -> 40000000
B8: Working Capital from LC | C8: 5000000 | D8: 1 | E8: =C8*D8 -> 5000000 | G8: Working Capital from LC | H8: 5000000 | I8: 1 | J8: =H8*I8 -> 5000000 | L8: Working Capital from LC | M8: 5000000 | N8: 1 | O8: =M8*N8 -> 5000000
B9: [Merchandise] Baseball Cap | C9: 65000 | D9: 5 | E9: =C9*D9 -> 325000 | G9: [Merchandise] Baseball Cap | H9: 65000 | I9: 10 | J9: =H9*I9 -> 650000 | L9: [Merchandise] Baseball Cap | M9: 65000 | N9: 15 | O9: =M9*N9 -> 975000
B10: [Merchandise] Baseball Shirt | C10: 165000 | D10: 5 | E10: =C10*D10 -> 825000 | G10: [Merchandise] Baseball Shirt | H10: 165000 | I10: 10 | J10: =H10*I10 -> 1650000 | L10: [Merchandise] Baseball Shirt | M10: 165000 | N10: 15 | O10: =M10*N10 -> 2475000
B11: [Merchandise] T-Shirt | C11: 120000 | D11: 5 | E11: =C11*D11 -> 600000 | G11: [Merchandise] T-Shirt | H11: 120000 | I11: 10 | J11: =H11*I11 -> 1200000 | L11: [Merchandise] T-Shirt | M11: 120000 | N11: 15 | O11: =M11*N11 -> 1800000
B12: [Merchandise] Stickers | C12: 12000 | D12: 20 | E12: =C12*D12 -> 240000 | G12: [Merchandise] Stickers | H12: 12000 | I12: 25 | J12: =H12*I12 -> 300000 | L12: [Merchandise] Stickers | M12: 12000 | N12: 35 | O12: =M12*N12 -> 420000
B13: [Merchandise] Blind Box Keychain | C13: 20000 | D13: 15 | E13: =C13*D13 -> 300000 | G13: [Merchandise] Blind Box Keychain | H13: 20000 | I13: 25 | J13: =H13*I13 -> 500000 | L13: [Merchandise] Blind Box Keychain | M13: 20000 | N13: 35 | O13: =M13*N13 -> 700000
B14: [Merchandise] Keychain AIESEC | C14: 15000 | D14: 5 | E14: =C14*D14 -> 75000 | G14: [Merchandise] Keychain AIESEC | H14: 15000 | I14: 10 | J14: =H14*I14 -> 150000 | L14: [Merchandise] Keychain AIESEC | M14: 15000 | N14: 15 | O14: =M14*N14 -> 225000
B15: [Merchandise] Button Pins | C15: 15000 | D15: 15 | E15: =C15*D15 -> 225000 | G15: [Merchandise] Button Pins | H15: 15000 | I15: 25 | J15: =H15*I15 -> 375000 | L15: [Merchandise] Button Pins | M15: 15000 | N15: 35 | O15: =M15*N15 -> 525000
B16: [Merchandise] Bundle A | C16: 250000 | D16: 10 | E16: =C16*D16 -> 2500000 | G16: [Merchandise] Bundle A | H16: 250000 | I16: 15 | J16: =H16*I16 -> 3750000 | L16: [Merchandise] Bundle A | M16: 250000 | N16: 20 | O16: =M16*N16 -> 5000000
... B23: LCP Pre-Meeting Delegates Fee | C23: 200000 | D23: 27 | E23: =C23*D23 -> 5400000 | G23: LCP Pre-Meeting Delegates Fee | H23: 200000 | I23: 27 | J23: =H23*I23 -> 5400000 | L23: LCP Pre-Meeting Delegates Fee | M23: 200000 | N23: 27 | O23: =M23*N23 -> 5400000
B24: TOTAL REVENUE | E24: =SUM(E5:E9) -> 429325000 | G24: TOTAL REVENUE | J24: =SUM(J5:J9) -> 429650000 | L24: TOTAL REVENUE | O24: =SUM(O5:O9) -> 429975000
B26: Expenses | E26: Total | G26: Expenses | J26: Total | L26: Expenses | O26: Total
B27: =$B$37 -> #REF! | E27: =E74 -> 31044608 | G27: =B27 -> #REF! | J27: =J74 -> 32001933 | L27: =G27 -> #REF! | O27: =O74 -> 34536876
B28: =B76 -> #REF! | E28: =E105 -> 2060700 | G28: =B28 -> #REF! | J28: =J105 -> 1340798 | L28: =G28 -> #REF! | O28: =O105 -> 940036
B29: =B107 -> #REF! | E29: =E127 -> 4652213 | G29: =B29 -> #REF! | J29: =J127 -> 1673697 | L29: =G29 -> #REF! | O29: =O127 -> 2631707
B30: =B129 -> #REF! | E30: =E142 -> 1673000 | G30: =B30 -> #REF! | J30: =J142 -> 536000 | L30: =G30 -> #REF! | O30: =O142 -> 1111000
B31: =B144 -> #REF! | E31: =E155 -> 2120000 | G31: =B31 -> #REF! | J31: =J155 -> 1652320 | L31: =G31 -> #REF! | O31: =O155 -> 1464000
B32: =B157 -> #REF! | E32: =E168 -> 347710200 | G32: =B32 -> #REF! | J32: =J168 -> 361116745 | L32: =G32 -> #REF! | O32: =O168 -> 336554100
B33: TOTAL EXPENSES | E33: =SUM(E27:E32) -> 389260721 | G33: TOTAL EXPENSES | J33: =SUM(J27:J32) -> 398321493 | L33: TOTAL EXPENSES | O33: =SUM(O27:O32) -> 377237719
B34: NET PROFIT | E34: =E24-E33 -> 40064279 | G34: NET PROFIT | J34: =J24-J33 -> 31328507 | L34: NET PROFIT | O34: =O24-O33 -> 52737281
B36: EXPENSE BREAKDOWN | G36: EXPENSE BREAKDOWN | L36: EXPENSE BREAKDOWN
B37: ='🏦COVER🏦'!D11 -> #REF! | C37: P | D37: Q | E37: Total | G37: =B37 -> #REF! | H37: P | I37: Q | J37: Total | L37: =G37 -> #REF! | M37: P | N37: Q | O37: Total
B38: Lanyard CDT | C38: 15000 | D38: 39 | E38: =C38*D38 -> 585000 | F38: =G38 -> Lanyard CDT | G38: Lanyard CDT | H38: 10000 | I38: 39 | J38: =H38*I38 -> 390000 | L38: Lanyard CDT | M38: 9000 | N38: 39 | O38: =M38*N38 -> 351000
B39: Baju CDT | C39: 80000 | D39: 39 | E39: =C39*D39 -> 3120000 | F39: =G39 -> Baju CDT | G39: Baju CDT | H39: 55000 | I39: 40 | J39: =H39*I39 -> 2200000 | L39: Baju CDT | M39: 80000 | N39: 39 | O39: =M39*N39 -> 3120000
B40: Baju Coach + MC WLL | C40: 70000 | D40: 45 | E40: =C40*D40 -> 3150000 | G40: Baju Coach + MC WLL | H40: 55000 | I40: 48 | J40: =H40*I40 -> 2640000 | L40: Baju Coach + MC WLL | M40: 70000 | N40: 45 | O40: =M40*N40 -> 3150000
B41: [Merchandise] Baseball Cap | C41: 45000 | D41: 15 | E41: =C41*D41 -> 675000 | F41: =G41 -> [Merchandise] Baseball Cap | G41: [Merchandise] Baseball Cap | H41: 40000 | I41: 25 | J41: =H41*I41 -> 1000000 | L41: [Merchandise] Baseball Cap | M41: 35000 | N41: 35 | O41: =M41*N41 -> 1225000
B42: [Merchandise] Baseball Shirt | C42: 135000 | D42: 5 | E42: =C42*D42 -> 675000 | F42: =G42 -> [Merchandise] Baseball Shirt | G42: [Merchandise] Baseball Shirt | H42: 120000 | I42: 25 | J42: =H42*I42 -> 3000000 | L42: [Merchandise] Baseball Shirt | M42: 100000 | N42: 35 | O42: =M42*N42 -> 3500000
B43: [Merchandise] T-Shirt | C43: 85000 | D43: 5 | E43: =C43*D43 -> 425000 | G43: [Merchandise] T-Shirt | H43: 80000 | I43: 10 | J43: =H43*I43 -> 800000 | L43: [Merchandise] T-Shirt | M43: 70000 | N43: 15 | O43: =M43*N43 -> 1050000
B44: [Merchandise] Button Pins | C44: 6000 | D44: 110 | E44: =C44*D44 -> 660000 | G44: [Merchandise] Button Pins | H44: 6000 | I44: 135 | J44: =H44*I44 -> 810000 | L44: [Merchandise] Button Pins | M44: 6000 | N44: 160 | O44: =M44*N44 -> 960000
B45: [Merchandise] Blind Box Keychain | C45: 8000 | D45: 110 | E45: =C45*D45 -> 880000 | G45: [Merchandise] Blind Box Keychain | H45: 7000 | I45: 135 | J45: =H45*I45 -> 945000 | L45: [Merchandise] Blind Box Keychain | M45: 6500 | N45: 160 | O45: =M45*N45 -> 1040000
B46: [Merchandise] Keychain | C46: 7000 | D46: 5 | E46: =C46*D46 -> 35000 | G46: [Merchandise] Keychain | H46: 6000 | I46: 10 | J46: =H46*I46 -> 60000 | L46: [Merchandise] Keychain | M46: 5000 | N46: 15 | O46: =M46*N46 -> 75000
B47: [Merchandise] Stickers | C47: 8000 | D47: 59 | E47: =C47*D47 -> 472000 | G47: [Merchandise] Stickers | H47: 5000 | I47: 70 | J47: =H47*I47 -> 350000 | L47: [Merchandise] Stickers | M47: 4000 | N47: 88 | O47: =M47*N47 -> 352000
B48: [CC Corner[ Yupi Hati | C48: 22999 | D48: 2 | E48: =C48*D48 -> 45998 | G48: [CC Corner[ Yupi Hati | H48: 22999 | I48: 3 | J48: =H48*I48 -> 68997 | L48: [CC Corner[ Yupi Hati | M48: 22999 | N48: 4 | O48: =M48*N48 -> 91996
...

Sheet Copy of 💰BUDGET PLAN💰
B1: =CONCATENATE('🏦COVER🏦'!D7," 💰Budget Plan💰") -> #REF!
B2: 💔Pessimistic Plan💔 | G2: 🤍Realistic Plan🤍 | L2: 💗Optimistic Plan💗
B3: REVENUE BREAKDOWN | G3: REVENUE BREAKDOWN | L3: REVENUE BREAKDOWN
B4: (revenue stream) | C4: P | D4: Q | E4: Total | G4: (revenue stream) | H4: P | I4: Q | J4: Total | L4: (revenue stream) | M4: P | N4: Q | O4: Total
B5: Delegates Fee | C5: 1150000 | D5: 320 | E5: =C5*D5 -> 368000000 | G5: Delegates Fee | H5: 1150000 | I5: 320 | J5: =H5*I5 -> 368000000 | L5: Delegates Fee | M5: 1150000 | N5: 320 | O5: =M5*N5 -> 368000000
B6: International Delegates Fee | C6: 1500000 | D6: 3 | E6: =C6*D6 -> 4500000 | G6: International Delegates Fee | H6: 1500000 | I6: 5 | J6: =H6*I6 -> 7500000 | L6: International Delegates Fee | M6: 1500000 | N6: 10 | O6: =M6*N6 -> 15000000
B7: Commitment Fee | C7: 50000 | D7: 323 | E7: =C7*D7 -> 16150000 | G7: Commitment Fee | H7: 50000 | I7: 325 | J7: =H7*I7 -> 16250000 | L7: Commitment Fee | M7: 50000 | N7: 330 | O7: =M7*N7 -> 16500000
B8: Working Capital from MC | C8: 40000000 | D8: 1 | E8: =C8*D8 -> 40000000 | G8: Working Capital from MC | H8: 40000000 | I8: 1 | J8: =H8*I8 -> 40000000 | L8: Working Capital from MC | M8: 40000000 | N8: 1 | O8: =M8*N8 -> 40000000
B9: Working Capital from LC | C9: 5000000 | D9: 1 | E9: =C9*D9 -> 5000000 | G9: Working Capital from LC | H9: 5000000 | I9: 1 | J9: =H9*I9 -> 5000000 | L9: Working Capital from LC | M9: 5000000 | N9: 1 | O9: =M9*N9 -> 5000000
B10: [Merchandise] Baseball Cap | C10: 65000 | D10: 5 | E10: =C10*D10 -> 325000 | G10: [Merchandise] Baseball Cap | H10: 65000 | I10: 10 | J10: =H10*I10 -> 650000 | L10: [Merchandise] Baseball Cap | M10: 65000 | N10: 15 | O10: =M10*N10 -> 975000
B11: [Merchandise] Baseball Shirt | C11: 165000 | D11: 5 | E11: =C11*D11 -> 825000 | G11: [Merchandise] Baseball Shirt | H11: 165000 | I11: 10 | J11: =H11*I11 -> 1650000 | L11: [Merchandise] Baseball Shirt | M11: 165000 | N11: 15 | O11: =M11*N11 -> 2475000
B12: [Merchandise] T-Shirt | C12: 120000 | D12: 5 | E12: =C12*D12 -> 600000 | G12: [Merchandise] T-Shirt | H12: 120000 | I12: 10 | J12: =H12*I12 -> 1200000 | L12: [Merchandise] T-Shirt | M12: 120000 | N12: 15 | O12: =M12*N12 -> 1800000
B13: [Merchandise] Stickers | C13: 12000 | D13: 20 | E13: =C13*D13 -> 240000 | G13: [Merchandise] Stickers | H13: 12000 | I13: 25 | J13: =H13*I13 -> 300000 | L13: [Merchandise] Stickers | M13: 12000 | N13: 35 | O13: =M13*N13 -> 420000
B14: [Merchandise] Blind Box Keychain | C14: 20000 | D14: 15 | E14: =C14*D14 -> 300000 | G14: [Merchandise] Blind Box Keychain | H14: 20000 | I14: 25 | J14: =H14*I14 -> 500000 | L14: [Merchandise] Blind Box Keychain | M14: 20000 | N14: 35 | O14: =M14*N14 -> 700000
B15: [Merchandise] Keychain AIESEC | C15: 15000 | D15: 5 | E15: =C15*D15 -> 75000 | G15: [Merchandise] Keychain AIESEC | H15: 15000 | I15: 10 | J15: =H15*I15 -> 150000 | L15: [Merchandise] Keychain AIESEC | M15: 15000 | N15: 15 | O15: =M15*N15 -> 225000
B16: [Merchandise] Button Pins | C16: 15000 | D16: 15 | E16: =C16*D16 -> 225000 | G16: [Merchandise] Button Pins | H16: 15000 | I16: 25 | J16: =H16*I16 -> 375000 | L16: [Merchandise] Button Pins | M16: 15000 | N16: 35 | O16: =M16*N16 -> 525000
... B26: Baju CDT | C26: 80000 | D26: 39 | E26: =C26*D26 -> 3120000 | G26: Baju CDT | H26: 80000 | I26: 39 | J26: =H26*I26 -> 3120000 | L26: Baju CDT | M26: 80000 | N26: 39 | O26: =M26*N26 -> 3120000
B27: TOTAL REVENUE | E27: =SUM(E5:E10) -> 433975000 | G27: TOTAL REVENUE | J27: =SUM(J5:J10) -> 437400000 | L27: TOTAL REVENUE | O27: =SUM(O5:O10) -> 445475000
B29: Expenses | E29: Total | G29: Expenses | J29: Total | L29: Expenses | O29: Total
B30: =$B$40 -> #REF! | E30: =E79 -> 31112608 | G30: =B30 -> #REF! | J30: =J79 -> 33496933 | L30: =G30 -> #REF! | O30: =O79 -> 34598876
B31: =B81 -> #REF! | E31: =E110 -> 2060700 | G31: =B31 -> #REF! | J31: =J110 -> 1340798 | L31: =G31 -> #REF! | O31: =O110 -> 940036
B32: =B112 -> #REF! | E32: =E132 -> 4652213 | G32: =B32 -> #REF! | J32: =J132 -> 3684072 | L32: =G32 -> #REF! | O32: =O132 -> 2631707
B33: =B134 -> #REF! | E33: =E147 -> 1673000 | G33: =B33 -> #REF! | J33: =J147 -> 1408000 | L33: =G33 -> #REF! | O33: =O147 -> 1111000
B34: =B149 -> #REF! | E34: =E160 -> 2120000 | G34: =B34 -> #REF! | J34: =J160 -> 1652320 | L34: =G34 -> #REF! | O34: =O160 -> 1464000
B35: =B162 -> #REF! | E35: =E174 -> 375905200 | G35: =B35 -> #REF! | J35: =J174 -> 380686745 | L35: =G35 -> #REF! | O35: =O174 -> 363914100
B36: TOTAL EXPENSES | E36: =SUM(E30:E35) -> 417523721 | G36: TOTAL EXPENSES | J36: =SUM(J30:J35) -> 422268868 | L36: TOTAL EXPENSES | O36: =SUM(O30:O35) -> 404659719
B37: NET PROFIT | E37: =E27-E36 -> 16451279 | G37: NET PROFIT | J37: =J27-J36 -> 15131132 | L37: NET PROFIT | O37: =O27-O36 -> 40815281
B39: EXPENSE BREAKDOWN | G39: EXPENSE BREAKDOWN | L39: EXPENSE BREAKDOWN
B40: ='🏦COVER🏦'!D11 -> #REF! | C40: P | D40: Q | E40: Total | G40: =B40 -> #REF! | H40: P | I40: Q | J40: Total | L40: =G40 -> #REF! | M40: P | N40: Q | O40: Total
B41: Lanyard CDT | C41: 15000 | D41: 39 | E41: =C41*D41 -> 585000 | F41: =G41 -> Lanyard CDT | G41: Lanyard CDT | H41: 10000 | I41: 39 | J41: =H41*I41 -> 390000 | L41: Lanyard CDT | M41: 9000 | N41: 39 | O41: =M41*N41 -> 351000
B42: Baju CDT | C42: 80000 | D42: 39 | E42: =C42*D42 -> 3120000 | F42: =G42 -> Baju CDT | G42: Baju CDT | H42: 80000 | I42: 39 | J42: =H42*I42 -> 3120000 | L42: Baju CDT | M42: 80000 | N42: 39 | O42: =M42*N42 -> 3120000
B43: Baju Coach + MC WLL | C43: 70000 | D43: 45 | E43: =C43*D43 -> 3150000 | G43: Baju Coach + MC WLL | H43: 70000 | I43: 45 | J43: =H43*I43 -> 3150000 | L43: Baju Coach + MC WLL | M43: 70000 | N43: 45 | O43: =M43*N43 -> 3150000
B44: [Merchandise] Baseball Cap | C44: 45000 | D44: 15 | E44: =C44*D44 -> 675000 | F44: =G44 -> [Merchandise] Baseball Cap | G44: [Merchandise] Baseball Cap | H44: 40000 | I44: 25 | J44: =H44*I44 -> 1000000 | L44: [Merchandise] Baseball Cap | M44: 35000 | N44: 35 | O44: =M44*N44 -> 1225000
B45: [Merchandise] Baseball Shirt | C45: 135000 | D45: 5 | E45: =C45*D45 -> 675000 | F45: =G45 -> [Merchandise] Baseball Shirt | G45: [Merchandise] Baseball Shirt | H45: 120000 | I45: 25 | J45: =H45*I45 -> 3000000 | L45: [Merchandise] Baseball Shirt | M45: 100000 | N45: 35 | O45: =M45*N45 -> 3500000
B46: [Merchandise] T-Shirt | C46: 85000 | D46: 5 | E46: =C46*D46 -> 425000 | G46: [Merchandise] T-Shirt | H46: 80000 | I46: 10 | J46: =H46*I46 -> 800000 | L46: [Merchandise] T-Shirt | M46: 70000 | N46: 15 | O46: =M46*N46 -> 1050000
B47: [Merchandise] Button Pins | C47: 6000 | D47: 110 | E47: =C47*D47 -> 660000 | G47: [Merchandise] Button Pins | H47: 6000 | I47: 135 | J47: =H47*I47 -> 810000 | L47: [Merchandise] Button Pins | M47: 6000 | N47: 160 | O47: =M47*N47 -> 960000
B48: [Merchandise] Blind Box Keychain | C48: 8000 | D48: 110 | E48: =C48*D48 -> 880000 | G48: [Merchandise] Blind Box Keychain | H48: 7000 | I48: 135 | J48: =H48*I48 -> 945000 | L48: [Merchandise] Blind Box Keychain | M48: 6500 | N48: 160 | O48: =M48*N48 -> 1040000
B49: [Merchandise] Keychain | C49: 7000 | D49: 5 | E49: =C49*D49 -> 35000 | G49: [Merchandise] Keychain | H49: 6000 | I49: 10 | J49: =H49*I49 -> 60000 | L49: [Merchandise] Keychain | M49: 5000 | N49: 15 | O49: =M49*N49 -> 75000
B50: [Merchandise] Stickers | C50: 8000 | D50: 59 | E50: =C50*D50 -> 472000 | G50: [Merchandise] Stickers | H50: 5000 | I50: 70 | J50: =H50*I50 -> 350000 | L50: [Merchandise] Stickers | M50: 4000 | N50: 88 | O50: =M50*N50 -> 352000
B51: [CC Corner] Print Paper for Drawing Photobooth | C51: 10000 | D51: 5 | E51: =C51*D51 -> 50000 | G51: [CC Corner] Print Paper for Drawing Photobooth | H51: 7000 | I51: 7 | J51: =H51*I51 -> 49000 | L51: [CC Corner] Print Paper for Drawing Photobooth | M51: 5000 | N51: 10 | O51: =M51*N51 -> 50000
...

Sheet with VIDEOTRON💰BUDGET PLAN💰
B1: =CONCATENATE('🏦COVER🏦'!D7," 💰Budget Plan💰") -> #REF!
B2: 💔Pessimistic Plan💔 | G2: 🤍Realistic Plan🤍 | L2: 💗Optimistic Plan💗
B3: REVENUE BREAKDOWN | G3: REVENUE BREAKDOWN | L3: REVENUE BREAKDOWN
B4: (revenue stream) | C4: P | D4: Q | E4: Total | G4: (revenue stream) | H4: P | I4: Q | J4: Total | L4: (revenue stream) | M4: P | N4: Q | O4: Total
B5: Delegates Fee | C5: 1100000 | D5: 320 | E5: =C5*D5 -> 352000000 | G5: Delegates Fee | H5: 1100000 | I5: 320 | J5: =H5*I5 -> 352000000 | L5: Delegates Fee | M5: 1100000 | N5: 320 | O5: =M5*N5 -> 352000000
B6: International Delegates Fee | C6: 1500000 | D6: 3 | E6: =C6*D6 -> 4500000 | G6: International Delegates Fee | H6: 1500000 | I6: 5 | J6: =H6*I6 -> 7500000 | L6: International Delegates Fee | M6: 1500000 | N6: 10 | O6: =M6*N6 -> 15000000
B7: Commitment Fee | C7: 50000 | D7: 323 | E7: =C7*D7 -> 16150000 | G7: Commitment Fee | H7: 50000 | I7: 325 | J7: =H7*I7 -> 16250000 | L7: Commitment Fee | M7: 50000 | N7: 330 | O7: =M7*N7 -> 16500000
B8: Working Capital from MC | C8: 40000000 | D8: 1 | E8: =C8*D8 -> 40000000 | G8: Working Capital from MC | H8: 40000000 | I8: 1 | J8: =H8*I8 -> 40000000 | L8: Working Capital from MC | M8: 40000000 | N8: 1 | O8: =M8*N8 -> 40000000
B9: Working Capital from LC | C9: 5000000 | D9: 1 | E9: =C9*D9 -> 5000000 | G9: Working Capital from LC | H9: 5000000 | I9: 1 | J9: =H9*I9 -> 5000000 | L9: Working Capital from LC | M9: 5000000 | N9: 1 | O9: =M9*N9 -> 5000000
B10: [Merchandise] Baseball Cap | C10: 65000 | D10: 5 | E10: =C10*D10 -> 325000 | G10: [Merchandise] Baseball Cap | H10: 65000 | I10: 10 | J10: =H10*I10 -> 650000 | L10: [Merchandise] Baseball Cap | M10: 65000 | N10: 15 | O10: =M10*N10 -> 975000
B11: [Merchandise] Baseball Shirt | C11: 165000 | D11: 5 | E11: =C11*D11 -> 825000 | G11: [Merchandise] Baseball Shirt | H11: 165000 | I11: 10 | J11: =H11*I11 -> 1650000 | L11: [Merchandise] Baseball Shirt | M11: 165000 | N11: 15 | O11: =M11*N11 -> 2475000
B12: [Merchandise] T-Shirt | C12: 120000 | D12: 5 | E12: =C12*D12 -> 600000 | G12: [Merchandise] T-Shirt | H12: 120000 | I12: 10 | J12: =H12*I12 -> 1200000 | L12: [Merchandise] T-Shirt | M12: 120000 | N12: 15 | O12: =M12*N12 -> 1800000
B13: [Merchandise] Stickers | C13: 12000 | D13: 20 | E13: =C13*D13 -> 240000 | G13: [Merchandise] Stickers | H13: 12000 | I13: 25 | J13: =H13*I13 -> 300000 | L13: [Merchandise] Stickers | M13: 12000 | N13: 35 | O13: =M13*N13 -> 420000
B14: [Merchandise] Blind Box Keychain | C14: 20000 | D14: 15 | E14: =C14*D14 -> 300000 | G14: [Merchandise] Blind Box Keychain | H14: 20000 | I14: 25 | J14: =H14*I14 -> 500000 | L14: [Merchandise] Blind Box Keychain | M14: 20000 | N14: 35 | O14: =M14*N14 -> 700000
B15: [Merchandise] Keychain AIESEC | C15: 15000 | D15: 5 | E15: =C15*D15 -> 75000 | G15: [Merchandise] Keychain AIESEC | H15: 15000 | I15: 10 | J15: =H15*I15 -> 150000 | L15: [Merchandise] Keychain AIESEC | M15: 15000 | N15: 15 | O15: =M15*N15 -> 225000
B16: [Merchandise] Button Pins | C16: 15000 | D16: 15 | E16: =C16*D16 -> 225000 | G16: [Merchandise] Button Pins | H16: 15000 | I16: 25 | J16: =H16*I16 -> 375000 | L16: [Merchandise] Button Pins | M16: 15000 | N16: 35 | O16: =M16*N16 -> 525000
... B26: Baju CDT | C26: 80000 | D26: 39 | E26: =C26*D26 -> 3120000 | G26: Baju CDT | H26: 80000 | I26: 39 | J26: =H26*I26 -> 3120000 | L26: Baju CDT | M26: 80000 | N26: 39 | O26: =M26*N26 -> 3120000
B27: TOTAL REVENUE | E27: =SUM(E5:E10) -> 417975000 | G27: TOTAL REVENUE | J27: =SUM(J5:J10) -> 421400000 | L27: TOTAL REVENUE | O27: =SUM(O5:O10) -> 429475000
B29: Expenses | E29: Total | G29: Expenses | J29: Total | L29: Expenses | O29: Total
B30: =$B$40 -> #REF! | E30: =E79 -> 31112608 | G30: =B30 -> #REF! | J30: =J79 -> 33496933 | L30: =G30 -> #REF! | O30: =O79 -> 34598876
B31: =B81 -> #REF! | E31: =E110 -> 2060700 | G31: =B31 -> #REF! | J31: =J110 -> 1340798 | L31: =G31 -> #REF! | O31: =O110 -> 940036
B32: =B112 -> #REF! | E32: =E132 -> 6267213 | G32: =B32 -> #REF! | J32: =J132 -> 4334072 | L32: =G32 -> #REF! | O32: =O132 -> 2631707
B33: =B134 -> #REF! | E33: =E147 -> 1673000 | G33: =B33 -> #REF! | J33: =J147 -> 1408000 | L33: =G33 -> #REF! | O33: =O147 -> 1111000
B34: =B149 -> #REF! | E34: =E160 -> 2120000 | G34: =B34 -> #REF! | J34: =J160 -> 1652320 | L34: =G34 -> #REF! | O34: =O160 -> 1464000
B35: =B162 -> #REF! | E35: =E174 -> 390905200 | G35: =B35 -> #REF! | J35: =J174 -> 381261745 | L35: =G35 -> #REF! | O35: =O174 -> 378914100
B36: TOTAL EXPENSES | E36: =SUM(E30:E35) -> 434138721 | G36: TOTAL EXPENSES | J36: =SUM(J30:J35) -> 423493868 | L36: TOTAL EXPENSES | O36: =SUM(O30:O35) -> 419659719
B37: NET PROFIT | E37: =E27-E36 -> -16163721 | G37: NET PROFIT | J37: =J27-J36 -> -2093868 | L37: NET PROFIT | O37: =O27-O36 -> 9815281
B39: EXPENSE BREAKDOWN | G39: EXPENSE BREAKDOWN | L39: EXPENSE BREAKDOWN
B40: ='🏦COVER🏦'!D11 -> #REF! | C40: P | D40: Q | E40: Total | G40: =B40 -> #REF! | H40: P | I40: Q | J40: Total | L40: =G40 -> #REF! | M40: P | N40: Q | O40: Total
B41: Lanyard CDT | C41: 15000 | D41: 39 | E41: =C41*D41 -> 585000 | F41: =G41 -> Lanyard CDT | G41: Lanyard CDT | H41: 10000 | I41: 39 | J41: =H41*I41 -> 390000 | L41: Lanyard CDT | M41: 9000 | N41: 39 | O41: =M41*N41 -> 351000
B42: Baju CDT | C42: 80000 | D42: 39 | E42: =C42*D42 -> 3120000 | F42: =G42 -> Baju CDT | G42: Baju CDT | H42: 80000 | I42: 39 | J42: =H42*I42 -> 3120000 | L42: Baju CDT | M42: 80000 | N42: 39 | O42: =M42*N42 -> 3120000
B43: Baju Coach + MC WLL | C43: 70000 | D43: 45 | E43: =C43*D43 -> 3150000 | G43: Baju Coach + MC WLL | H43: 70000 | I43: 45 | J43: =H43*I43 -> 3150000 | L43: Baju Coach + MC WLL | M43: 70000 | N43: 45 | O43: =M43*N43 -> 3150000
B44: [Merchandise] Baseball Cap | C44: 45000 | D44: 15 | E44: =C44*D44 -> 675000 | F44: =G44 -> [Merchandise] Baseball Cap | G44: [Merchandise] Baseball Cap | H44: 40000 | I44: 25 | J44: =H44*I44 -> 1000000 | L44: [Merchandise] Baseball Cap | M44: 35000 | N44: 35 | O44: =M44*N44 -> 1225000
B45: [Merchandise] Baseball Shirt | C45: 135000 | D45: 5 | E45: =C45*D45 -> 675000 | F45: =G45 -> [Merchandise] Baseball Shirt | G45: [Merchandise] Baseball Shirt | H45: 120000 | I45: 25 | J45: =H45*I45 -> 3000000 | L45: [Merchandise] Baseball Shirt | M45: 100000 | N45: 35 | O45: =M45*N45 -> 3500000
B46: [Merchandise] T-Shirt | C46: 85000 | D46: 5 | E46: =C46*D46 -> 425000 | G46: [Merchandise] T-Shirt | H46: 80000 | I46: 10 | J46: =H46*I46 -> 800000 | L46: [Merchandise] T-Shirt | M46: 70000 | N46: 15 | O46: =M46*N46 -> 1050000
B47: [Merchandise] Button Pins | C47: 6000 | D47: 110 | E47: =C47*D47 -> 660000 | G47: [Merchandise] Button Pins | H47: 6000 | I47: 135 | J47: =H47*I47 -> 810000 | L47: [Merchandise] Button Pins | M47: 6000 | N47: 160 | O47: =M47*N47 -> 960000
B48: [Merchandise] Blind Box Keychain | C48: 8000 | D48: 110 | E48: =C48*D48 -> 880000 | G48: [Merchandise] Blind Box Keychain | H48: 7000 | I48: 135 | J48: =H48*I48 -> 945000 | L48: [Merchandise] Blind Box Keychain | M48: 6500 | N48: 160 | O48: =M48*N48 -> 1040000
B49: [Merchandise] Keychain | C49: 7000 | D49: 5 | E49: =C49*D49 -> 35000 | G49: [Merchandise] Keychain | H49: 6000 | I49: 10 | J49: =H49*I49 -> 60000 | L49: [Merchandise] Keychain | M49: 5000 | N49: 15 | O49: =M49*N49 -> 75000
B50: [Merchandise] Stickers | C50: 8000 | D50: 59 | E50: =C50*D50 -> 472000 | G50: [Merchandise] Stickers | H50: 5000 | I50: 70 | J50: =H50*I50 -> 350000 | L50: [Merchandise] Stickers | M50: 4000 | N50: 88 | O50: =M50*N50 -> 352000
B51: [CC Corner] Print Paper for Drawing Photobooth | C51: 10000 | D51: 5 | E51: =C51*D51 -> 50000 | G51: [CC Corner] Print Paper for Drawing Photobooth | H51: 7000 | I51: 7 | J51: =H51*I51 -> 49000 | L51: [CC Corner] Print Paper for Drawing Photobooth | M51: 5000 | N51: 10 | O51: =M51*N51 -> 50000
...

Sheet 💰BUDGET PLAN💰
B1: 💰Budget Plan💰
B2: Pessimistic Plan | G2: Moderate Plan | L2: Optimistic Plan
B3: REVENUE BREAKDOWN | G3: REVENUE BREAKDOWN | L3: REVENUE BREAKDOWN
B4: (revenue stream) | C4: P | D4: Q | E4: Total | G4: (revenue stream) | H4: P | I4: Q | J4: Total | L4: (revenue stream) | M4: P | N4: Q | O4: Total
E5: =C5*D5 -> 0 | J5: =H5*I5 -> 0 | O5: =M5*N5 -> 0
E6: =C6*D6 -> 0 | J6: =H6*I6 -> 0 | O6: =M6*N6 -> 0
E7: =C7*D7 -> 0 | J7: =H7*I7 -> 0 | O7: =M7*N7 -> 0
E8: =C8*D8 -> 0 | J8: =H8*I8 -> 0 | O8: =M8*N8 -> 0
E9: =C9*D9 -> 0 | J9: =H9*I9 -> 0 | O9: =M9*N9 -> 0
E10: =C10*D10 -> 0 | J10: =H10*I10 -> 0 | O10: =M10*N10 -> 0
E11: =C11*D11 -> 0 | J11: =H11*I11 -> 0 | O11: =M11*N11 -> 0
E12: =C12*D12 -> 0 | J12: =H12*I12 -> 0 | O12: =M12*N12 -> 0
E13: =C13*D13 -> 0 | J13: =H13*I13 -> 0 | O13: =M13*N13 -> 0
E14: =C14*D14 -> 0 | J14: =H14*I14 -> 0 | O14: =M14*N14 -> 0
E15: =C15*D15 -> 0 | J15: =H15*I15 -> 0 | O15: =M15*N15 -> 0
E16: =C16*D16 -> 0 | J16: =H16*I16 -> 0 | O16: =M16*N16 -> 0
... E26: =C26*D26 -> 0 | J26: =H26*I26 -> 0 | O26: =M26*N26 -> 0
B27: TOTAL REVENUE | E27: =SUM(E5:E10) -> 0 | G27: TOTAL REVENUE | J27: =SUM(J5:J10) -> 0 | L27: TOTAL REVENUE | O27: =SUM(O5:O10) -> 0
B29: Expenses | E29: Total | G29: Expenses | J29: Total | L29: Expenses | O29: Total
B30: =$B$40 -> DIVISI A | E30: =E77 -> 0 | G30: =B30 -> DIVISI A | J30: =J77 -> 0 | L30: =G30 -> DIVISI A | O30: =O77 -> 0
B31: =B79 -> #REF! | E31: =E108 -> 0 | G31: =B31 -> #REF! | J31: =J108 -> 0 | L31: =G31 -> #REF! | O31: =O108 -> 0
B32: =B110 -> #REF! | E32: =E130 -> 0 | G32: =B32 -> #REF! | J32: =J130 -> 0 | L32: =G32 -> #REF! | O32: =O130 -> 0
B33: =B132 -> #REF! | E33: =E145 -> 0 | G33: =B33 -> #REF! | J33: =J145 -> 0 | L33: =G33 -> #REF! | O33: =O145 -> 0
B34: =B147 -> #REF! | E34: =E158 -> 0 | G34: =B34 -> #REF! | J34: =J158 -> 0 | L34: =G34 -> #REF! | O34: =O158 -> 0
B35: =B160 -> #REF! | E35: =E171 -> 0 | G35: =B35 -> #REF! | J35: =J171 -> 0 | L35: =G35 -> #REF! | O35: =O171 -> 0
B36: TOTAL EXPENSES | E36: =SUM(E30:E35) -> 0 | G36: TOTAL EXPENSES | J36: =SUM(J30:J35) -> 0 | L36: TOTAL EXPENSES | O36: =SUM(O30:O35) -> 0
B37: NET PROFIT | E37: =E27-E36 -> 0 | G37: NET PROFIT | J37: =J27-J36 -> 0 | L37: NET PROFIT | O37: =O27-O36 -> 0
B39: EXPENSE BREAKDOWN | G39: EXPENSE BREAKDOWN | L39: EXPENSE BREAKDOWN
B40: DIVISI A | C40: P | D40: Q | E40: Total | G40: =B40 -> DIVISI A | H40: P | I40: Q | J40: Total | L40: =G40 -> DIVISI A | M40: P | N40: Q | O40: Total
E41: =C41*D41 -> 0 | F41: =G41 | J41: =H41*I41 -> 0 | O41: =M41*N41 -> 0
E42: =C42*D42 -> 0 | F42: =G42 | J42: =H42*I42 -> 0 | O42: =M42*N42 -> 0
E43: =C43*D43 -> 0 | J43: =H43*I43 -> 0 | O43: =M43*N43 -> 0
E44: =C44*D44 -> 0 | F44: =G44 | J44: =H44*I44 -> 0 | O44: =M44*N44 -> 0
E45: =C45*D45 -> 0 | F45: =G45 | J45: =H45*I45 -> 0 | O45: =M45*N45 -> 0
E46: =C46*D46 -> 0 | J46: =H46*I46 -> 0 | O46: =M46*N46 -> 0
E47: =C47*D47 -> 0 | J47: =H47*I47 -> 0 | O47: =M47*N47 -> 0
E48: =C48*D48 -> 0 | J48: =H48*I48 -> 0 | O48: =M48*N48 -> 0
E49: =C49*D49 -> 0 | J49: =H49*I49 -> 0 | O49: =M49*N49 -> 0
E50: =C50*D50 -> 0 | J50: =H50*I50 -> 0 | O50: =M50*N50 -> 0
E51: =C51*D51 -> 0 | J51: =H51*I51 -> 0 | O51: =M51*N51 -> 0
...

Sheet 💸BUDGET REALIZED💸
B1: Budget Realized
B3: 💲REVENUE💲 | E3: Total
B4: =B8 -> (revenue stream) | E4: =E18 -> 0
B5: TOTAL REVENUE | E5: =SUM(E4) -> 0
B7: REVENUE BREAKDOWN | G7: % Realization
B8: ='💰BUDGET PLAN💰'!G4 -> (revenue stream) | C8: P | D8: Q | E8: Total | G8: Pessimistic | H8: Realistic | I8: Optimistic | M8: P | N8: R | O8: O
E9: =C9*D9 -> 0 | G9: =IF(M9=0,"",E9/M9) | H9: =IF(N9=0,"",E9/N9) | I9: =IF(O9=0,"",E9/O9) | K9: =IF(G9="","",IF(I9>=1,$I$8,IF(H9>=1,$H$8,$G$8))) | M9: =SUMIF('💰BUDGET PLAN💰'!$B$5:$B$10,B9,'💰BUDGET PLAN💰'!$E$5:$E$10) -> 0 | N9: =SUMIF('💰BUDGET PLAN💰'!$G$5:$G$10,B9,'💰BUDGET PLAN💰'!$J$5:$J$10) -> 0 | O9: =SUMIF('💰BUDGET PLAN💰'!$L$5:$L$10,B9,'💰BUDGET PLAN💰'!$O$5:$O$10) -> 0
E10: =C10*D10 -> 0 | G10: =IF(M10=0,"",E10/M10) | H10: =IF(N10=0,"",E10/N10) | I10: =IF(O10=0,"",E10/O10) | K10: =IF(G10="","",IF(I10>=1,$I$8,IF(H10>=1,$H$8,$G$8))) | M10: =SUMIF('💰BUDGET PLAN💰'!$B$5:$B$10,B10,'💰BUDGET PLAN💰'!$E$5:$E$10) -> 0 | N10: =SUMIF('💰BUDGET PLAN💰'!$G$5:$G$10,B10,'💰BUDGET PLAN💰'!$J$5:$J$10) -> 0 | O10: =SUMIF('💰BUDGET PLAN💰'!$L$5:$L$10,B10,'💰BUDGET PLAN💰'!$O$5:$O$10) -> 0
E11: =C11*D11 -> 0 | G11: =IF(M11=0,"",E11/M11) | H11: =IF(N11=0,"",E11/N11) | I11: =IF(O11=0,"",E11/O11) | K11: =IF(G11="","",IF(I11>=1,$I$8,IF(H11>=1,$H$8,$G$8))) | M11: =SUMIF('💰BUDGET PLAN💰'!$B$5:$B$10,B11,'💰BUDGET PLAN💰'!$E$5:$E$10) -> 0 | N11: =SUMIF('💰BUDGET PLAN💰'!$G$5:$G$10,B11,'💰BUDGET PLAN💰'!$J$5:$J$10) -> 0 | O11: =SUMIF('💰BUDGET PLAN💰'!$L$5:$L$10,B11,'💰BUDGET PLAN💰'!$O$5:$O$10) -> 0
E12: =C12*D12 -> 0 | G12: =IF(M12=0,"",E12/M12) | H12: =IF(N12=0,"",E12/N12) | I12: =IF(O12=0,"",E12/O12) | K12: =IF(G12="","",IF(I12>=1,$I$8,IF(H12>=1,$H$8,$G$8))) | M12: =SUMIF('💰BUDGET PLAN💰'!$B$5:$B$10,B12,'💰BUDGET PLAN💰'!$E$5:$E$10) -> 0 | N12: =SUMIF('💰BUDGET PLAN💰'!$G$5:$G$10,B12,'💰BUDGET PLAN💰'!$J$5:$J$10) -> 0 | O12: =SUMIF('💰BUDGET PLAN💰'!$L$5:$L$10,B12,'💰BUDGET PLAN💰'!$O$5:$O$10) -> 0
E13: =C13*D13 -> 0 | G13: =IF(M13=0,"",E13/M13) | H13: =IF(N13=0,"",E13/N13) | I13: =IF(O13=0,"",E13/O13)
E14: =C14*D14 -> 0 | G14: =IF(M14=0,"",E14/M14) | H14: =IF(N14=0,"",E14/N14) | I14: =IF(O14=0,"",E14/O14)
E15: =C15*D15 -> 0 | G15: =IF(M15=0,"",E15/M15) | H15: =IF(N15=0,"",E15/N15) | I15: =IF(O15=0,"",E15/O15)
E16: =C16*D16 -> 0 | G16: =IF(M16=0,"",E16/M16) | H16: =IF(N16=0,"",E16/N16) | I16: =IF(O16=0,"",E16/O16)
E17: =C17*D17 -> 0 | G17: =IF(M17=0,"",E17/M17) | H17: =IF(N17=0,"",E17/N17) | I17: =IF(O17=0,"",E17/O17)
B18: TOTAL REVENUE | E18: =SUM(E9:E17) -> 0 | G18: =IF(M18=0,"",E18/M18) | H18: =IF(N18=0,"",E18/N18) | I18: =IF(O18=0,"",E18/O18) | K18: =IF(G18="","",IF(I18>=1,$I$8,IF(H18>=1,$H$8,$G$8))) | M18: ='💰BUDGET PLAN💰'!E27 -> 0 | N18: ='💰BUDGET PLAN💰'!J27 -> 0 | O18: ='💰BUDGET PLAN💰'!O27 -> 0
B20: 📉EXPENSE📉 | E20: Total
B21: =B32 -> ACARA | E21: =E47 -> 1000000 | K21: =IF(G21="","",IF(I21>=1,$I$8,IF(H21>=1,$H$8,$G$8))) | M21: ='💰BUDGET PLAN💰'!E30 -> 0 | N21: ='💰BUDGET PLAN💰'!J30 -> 0 | O21: =#REF! -> #REF!
B22: =B49 -> Divisi A | E22: =E78 -> 0 | K22: =IF(G22="","",IF(I22>=1,$I$8,IF(H22>=1,$H$8,$G$8))) | M22: ='💰BUDGET PLAN💰'!E31 -> 0 | N22: ='💰BUDGET PLAN💰'!J31 -> 0 | O22: =#REF! -> #REF!
B23: =B80 -> Divisi A | E23: =E100 -> 0 | K23: =IF(G23="","",IF(I23>=1,$I$8,IF(H23>=1,$H$8,$G$8))) | M23: ='💰BUDGET PLAN💰'!E32 -> 0 | N23: ='💰BUDGET PLAN💰'!J32 -> 0 | O23: =#REF! -> #REF!
B24: =B102 -> Divisi A | E24: =E115 -> 0 | K24: =IF(G24="","",IF(I24>=1,$I$8,IF(H24>=1,$H$8,$G$8))) | M24: ='💰BUDGET PLAN💰'!E33 -> 0 | N24: ='💰BUDGET PLAN💰'!J33 -> 0 | O24: =#REF! -> #REF!
B25: =B117 -> Divisi A | E25: =E127 -> 0 | K25: =IF(G25="","",IF(I25>=1,$I$8,IF(H25>=1,$H$8,$G$8))) | M25: ='💰BUDGET PLAN💰'!E34 -> 0 | N25: ='💰BUDGET PLAN💰'!J34 -> 0 | O25: =#REF! -> #REF!
B26: =B129 -> Divisi A | E26: =E139 -> 0 | K26: =IF(G26="","",IF(I26>=1,$I$8,IF(H26>=1,$H$8,$G$8))) | M26: ='💰BUDGET PLAN💰'!E35 -> 0 | N26: ='💰BUDGET PLAN💰'!J35 -> 0 | O26: =#REF! -> #REF!
B27: TOTAL EXPENSES | E27: =SUM(E21:E26) -> 1000000 | K27: =IF(G27="","",IF(I27>=1,$I$8,IF(H27>=1,$H$8,$G$8))) | M27: =#REF! -> #REF! | N27: =#REF! -> #REF! | O27: =#REF! -> #REF!
B29: 💲NET PROFIT💲 | E29: =E5-E27 -> -1000000 | K29: =IF(G29="","",IF(I29>=1,$I$8,IF(H29>=1,$H$8,$G$8))) | M29: ='💰BUDGET PLAN💰'!E37 -> 0 | N29: ='💰BUDGET PLAN💰'!J37 -> 0 | O29: ='💰BUDGET PLAN💰'!O37 -> 0
B31: EXPENSE BREAKDOWN
B32: ACARA | C32: P | D32: Q | E32: Total | G32: % Realization | M32: P | N32: R | O32: O
B33: banner | C33: 200000 | D33: 5 | E33: =C33*D33 -> 1000000 | G33: =IF(M33=0,"",E33/M33) | H33: =IF(N33=0,"",E33/N33) | I33: =IF(O33=0,"",E33/O33) | K33: =IF(G33="","",IF(I33>=1,$I$8,IF(H33>=1,$H$8,$G$8))) | M33: =SUMIF('💰BUDGET PLAN💰'!$B$41:$B$69,B33,'💰BUDGET PLAN💰'!$E$41:$E$69) -> 0 | N33: =SUMIF('💰BUDGET PLAN💰'!$G$41:$G$69,B33,'💰BUDGET PLAN💰'!$J$41:$J$69) -> 0 | O33: =SUMIF('💰BUDGET PLAN💰'!$L$41:$L$69,'💸BUDGET REALIZED💸'!B33,'💰BUDGET PLAN💰'!$O$41:$O$69) -> 0
E34: =C34*D34 -> 0 | G34: =IF(M34=0,"",E34/M34) | H34: =IF(N34=0,"",E34/N34) | I34: =IF(O34=0,"",E34/O34) | K34: =IF(G34="","",IF(I34>=1,$I$8,IF(H34>=1,$H$8,$G$8))) | M34: =SUMIF('💰BUDGET PLAN💰'!$B$41:$B$69,B34,'💰BUDGET PLAN💰'!$E$41:$E$69) -> 0 | N34: =SUMIF('💰BUDGET PLAN💰'!$G$41:$G$69,B34,'💰BUDGET PLAN💰'!$J$41:$J$69) -> 0 | O34: =SUMIF('💰BUDGET PLAN💰'!$L$41:$L$69,'💸BUDGET REALIZED💸'!B34,'💰BUDGET PLAN💰'!$O$41:$O$69) -> 0
E35: =C35*D35 -> 0 | G35: =IF(M35=0,"",E35/M35) | H35: =IF(N35=0,"",E35/N35) | I35: =IF(O35=0,"",E35/O35) | K35: =IF(G35="","",IF(I35>=1,$I$8,IF(H35>=1,$H$8,$G$8))) | M35: =SUMIF('💰BUDGET PLAN💰'!$B$41:$B$69,B35,'💰BUDGET PLAN💰'!$E$41:$E$69) -> 0 | N35: =SUMIF('💰BUDGET PLAN💰'!$G$41:$G$69,B35,'💰BUDGET PLAN💰'!$J$41:$J$69) -> 0 | O35: =SUMIF('💰BUDGET PLAN💰'!$L$41:$L$69,'💸BUDGET REALIZED💸'!B35,'💰BUDGET PLAN💰'!$O$41:$O$69) -> 0
E36: =C36*D36 -> 0 | G36: =IF(M36=0,"",E36/M36) | H36: =IF(N36=0,"",E36/N36) | I36: =IF(O36=0,"",E36/O36) | K36: =IF(G36="","",IF(I36>=1,$I$8,IF(H36>=1,$H$8,$G$8))) | M36: =SUMIF('💰BUDGET PLAN💰'!$B$41:$B$69,B36,'💰BUDGET PLAN💰'!$E$41:$E$69) -> 0 | N36: =SUMIF('💰BUDGET PLAN💰'!$G$41:$G$69,B36,'💰BUDGET PLAN💰'!$J$41:$J$69) -> 0 | O36: =SUMIF('💰BUDGET PLAN💰'!$L$41:$L$69,'💸BUDGET REALIZED💸'!B36,'💰BUDGET PLAN💰'!$O$41:$O$69) -> 0
E37: =C37*D37 -> 0 | G37: =IF(M37=0,"",E37/M37) | H37: =IF(N37=0,"",E37/N37) | I37: =IF(O37=0,"",E37/O37) | K37: =IF(G37="","",IF(I37>=1,$I$8,IF(H37>=1,$H$8,$G$8))) | M37: =SUMIF('💰BUDGET PLAN💰'!$B$41:$B$69,B37,'💰BUDGET PLAN💰'!$E$41:$E$69) -> 0 | N37: =SUMIF('💰BUDGET PLAN💰'!$G$41:$G$69,B37,'💰BUDGET PLAN💰'!$J$41:$J$69) -> 0 | O37: =SUMIF('💰BUDGET PLAN💰'!$L$41:$L$69,'💸BUDGET REALIZED💸'!B37,'💰BUDGET PLAN💰'!$O$41:$O$69) -> 0
E38: =C38*D38 -> 0 | G38: =IF(M38=0,"",E38/M38) | H38: =IF(N38=0,"",E38/N38) | I38: =IF(O38=0,"",E38/O38) | K38: =IF(G38="","",IF(I38>=1,$I$8,IF(H38>=1,$H$8,$G$8))) | M38: =SUMIF('💰BUDGET PLAN💰'!$B$41:$B$69,B38,'💰BUDGET PLAN💰'!$E$41:$E$69) -> 0 | N38: =SUMIF('💰BUDGET PLAN💰'!$G$41:$G$69,B38,'💰BUDGET PLAN💰'!$J$41:$J$69) -> 0 | O38: =SUMIF('💰BUDGET PLAN💰'!$L$41:$L$69,'💸BUDGET REALIZED💸'!B38,'💰BUDGET PLAN💰'!$O$41:$O$69) -> 0
E39: =C39*D39 -> 0 | G39: =IF(M39=0,"",E39/M39) | H39: =IF(N39=0,"",E39/N39) | I39: =IF(O39=0,"",E39/O39) | K39: =IF(G39="","",IF(I39>=1,$I$8,IF(H39>=1,$H$8,$G$8))) | M39: =SUMIF('💰BUDGET PLAN💰'!$B$41:$B$69,B39,'💰BUDGET PLAN💰'!$E$41:$E$69) -> 0 | N39: =SUMIF('💰BUDGET PLAN💰'!$G$41:$G$69,B39,'💰BUDGET PLAN💰'!$J$41:$J$69) -> 0 | O39: =SUMIF('💰BUDGET PLAN💰'!$L$41:$L$69,'💸BUDGET REALIZED💸'!B39,'💰BUDGET PLAN💰'!$O$41:$O$69) -> 0
E40: =C40*D40 -> 0 | G40: =IF(M40=0,"",E40/M40) | H40: =IF(N40=0,"",E40/N40) | I40: =IF(O40=0,"",E40/O40) | K40: =IF(G40="","",IF(I40>=1,$I$8,IF(H40>=1,$H$8,$G$8))) | M40: =SUMIF('💰BUDGET PLAN💰'!$B$41:$B$69,B40,'💰BUDGET PLAN💰'!$E$41:$E$69) -> 0 | N40: =SUMIF('💰BUDGET PLAN💰'!$G$41:$G$69,B40,'💰BUDGET PLAN💰'!$J$41:$J$69) -> 0 | O40: =SUMIF('💰BUDGET PLAN💰'!$L$41:$L$69,'💸BUDGET REALIZED💸'!B40,'💰BUDGET PLAN💰'!$O$41:$O$69) -> 0
E41: =C41*D41 -> 0 | G41: =IF(M41=0,"",E41/M41) | H41: =IF(N41=0,"",E41/N41) | I41: =IF(O41=0,"",E41/O41) | K41: =IF(G41="","",IF(I41>=1,$I$8,IF(H41>=1,$H$8,$G$8))) | M41: =SUMIF('💰BUDGET PLAN💰'!$B$41:$B$69,B41,'💰BUDGET PLAN💰'!$E$41:$E$69) -> 0 | N41: =SUMIF('💰BUDGET PLAN💰'!$G$41:$G$69,B41,'💰BUDGET PLAN💰'!$J$41:$J$69) -> 0 | O41: =SUMIF('💰BUDGET PLAN💰'!$L$41:$L$69,'💸BUDGET REALIZED💸'!B41,'💰BUDGET PLAN💰'!$O$41:$O$69) -> 0
E42: =C42*D42 -> 0 | G42: =IF(M42=0,"",E42/M42) | H42: =IF(N42=0,"",E42/N42) | I42: =IF(O42=0,"",E42/O42) | K42: =IF(G42="","",IF(I42>=1,$I$8,IF(H42>=1,$H$8,$G$8))) | M42: =SUMIF('💰BUDGET PLAN💰'!$B$41:$B$69,B42,'💰BUDGET PLAN💰'!$E$41:$E$69) -> 0 | N42: =SUMIF('💰BUDGET PLAN💰'!$G$41:$G$69,B42,'💰BUDGET PLAN💰'!$J$41:$J$69) -> 0 | O42: =SUMIF('💰BUDGET PLAN💰'!$L$41:$L$69,'💸BUDGET REALIZED💸'!B42,'💰BUDGET PLAN💰'!$O$41:$O$69) -> 0
E43: =C43*D43 -> 0 | G43: =IF(M43=0,"",E43/M43) | H43: =IF(N43=0,"",E43/N43) | I43: =IF(O43=0,"",E43/O43)
E44: =C44*D44 -> 0 | G44: =IF(M44=0,"",E44/M44) | H44: =IF(N44=0,"",E44/N44) | I44: =IF(O44=0,"",E44/O44)
E45: =C45*D45 -> 0 | G45: =IF(M45=0,"",E45/M45) | H45: =IF(N45=0,"",E45/N45) | I45: =IF(O45=0,"",E45/O45)
...

Sheet 🚨CASHFLOW🚨
A1: ='TRACKING 💎MERCH💎'!A1 | I1: ⚠️ FILL IN THE COLOURLESS CELL ONLY⚠️ | R1: ⚠️ FILL IN THE COLOURLESS CELL ONLY⚠️ | AA1: ⚠️ FILL IN THE COLOURLESS CELL ONLY⚠️
I2: CASH FLOW | R2: 👑Cash Flow👑 | AA2: 👑Cash Flow👑
B3: Cash Growth | I3: Date | J3: Description | K3: Division | L3: Cash In | M3: Cash Out | N3: Transaction Proof (Attach the link and make it accessible) | O3: Cash Balance | P3: Ending Cash Balance | Q3: Q1 | R3: Date | S3: Description | T3: Division | U3: Cash In | V3: Cash Out | W3: Transaction Proof (Attach the link and make it accessible) | X3: Cash Balance | Y3: Ending Cash Balance | Z3: Q2 | AA3: Date | AB3: Description | AC3: Division | AD3: Cash In | AE3: Cash Out | AF3: Transaction Proof (Attach the link and make it accessible) | AG3: Cash Balance | AH3: Ending Cash Balance | AI3: Q3
B4: Period | D4: Total Cash In | E4: Total Cash Out | F4: Cash Balance | G4: % Growth | L4: =SUM(L6:L305) -> 130000 | M4: =SUM(M6:M305) -> 42000 | P4: =IF(SUM(L6:L1305)+SUM(M6:M1305)=0,0,SUM(L6:L1305)-SUM(M6:M1305)) -> 88000 | U4: =SUM(U6:U305) -> 0 | V4: =SUM(V6:V305) -> 0 | Y4: =IF(SUM(U6:U1305)+SUM(V6:V1305)=0,0,SUM(U6:U1305)-SUM(V6:V1305)) -> 0 | AD4: =SUM(AD6:AD305) -> 0 | AE4: =SUM(AE6:AE305) -> 0 | AH4: =IF(SUM(AD6:AD1305)+SUM(AE6:AE1305)=0,0,SUM(AD6:AD1305)-SUM(AE6:AE1305)) -> 0
F5: 24000000
B6: Q1 | D6: =sum(L6:L49) -> 130000 | E6: =sum(M6:M305) -> 42000 | F6: =IF(D6+E6=0," ",F5+D6-E6) -> 24088000 | G6: =(F6-F5)/F5 -> 0.0036666667 | I6: 46194 | J6: Beli bahan modal kain | L6: 100000 | O6: =IF(L6+M6=0," ",O4+L6-M6) -> 100000 | X6: =IF(U6+V6=0," ",X4+U6-V6) | AG6: =IF(AD6+AE6=0," ",AG4+AD6-AE6)
M7: 2000 | O7: =IF(L7+M7=0," ",O6+L7-M7) -> 98000 | P7: =P13 | X7: =IF(U7+V7=0," ",X6+U7-V7) | AG7: =IF(AD7+AE7=0," ",AG6+AD7-AE7)
L8: 30000 | O8: =IF(L8+M8=0," ",O7+L8-M8) -> 128000 | X8: =IF(U8+V8=0," ",X7+U8-V8) | AG8: =IF(AD8+AE8=0," ",AG7+AD8-AE8)
M9: 40000 | O9: =IF(L9+M9=0," ",O8+L9-M9) -> 88000 | X9: =IF(U9+V9=0," ",X8+U9-V9) | AG9: =IF(AD9+AE9=0," ",AG8+AD9-AE9)
B10: Q2 | D10: =sum(U4) -> 0 | E10: =sum(V4) -> 0 | F10: =IF(D10+E10=0," ",F5+D10-E10) | G10: =(F10-F5)/F5 -> #VALUE! | O10: =IF(L10+M10=0," ",O9+L10-M10) | X10: =IF(U10+V10=0," ",X9+U10-V10) | AG10: =IF(AD10+AE10=0," ",AG9+AD10-AE10)
O11: =IF(L11+M11=0," ",O10+L11-M11) | X11: =IF(U11+V11=0," ",X10+U11-V11) | AG11: =IF(AD11+AE11=0," ",AG10+AD11-AE11)
O12: =IF(L12+M12=0," ",O11+L12-M12) | X12: =IF(U12+V12=0," ",X11+U12-V12) | AG12: =IF(AD12+AE12=0," ",AG11+AD12-AE12)
O13: =IF(L13+M13=0," ",O12+L13-M13) | X13: =IF(U13+V13=0," ",X12+U13-V13) | AG13: =IF(AD13+AE13=0," ",AG12+AD13-AE13)
B14: Q3 | D14: =sum(L14:L57) -> 0 | E14: =sum(M14:M313) -> 0 | F14: =IF(D14+E14=0," ",F13+D14-E14) | G14: =(F14-F5)/F5 -> #VALUE! | O14: =IF(L14+M14=0," ",O13+L14-M14) | X14: =IF(U14+V14=0," ",X13+U14-V14) | AG14: =IF(AD14+AE14=0," ",AG13+AD14-AE14)
O15: =IF(L15+M15=0," ",O14+L15-M15) | X15: =IF(U15+V15=0," ",X14+U15-V15) | AG15: =IF(AD15+AE15=0," ",AG14+AD15-AE15)
O16: =IF(L16+M16=0," ",O15+L16-M16) | X16: =IF(U16+V16=0," ",X15+U16-V16) | AG16: =IF(AD16+AE16=0," ",AG15+AD16-AE16)
O17: =IF(L17+M17=0," ",O16+L17-M17) | X17: =IF(U17+V17=0," ",X16+U17-V17) | AG17: =IF(AD17+AE17=0," ",AG16+AD17-AE17)
B18: Q4 | D18: =sum(L18:L61) -> 0 | E18: =sum(M18:M317) -> 0 | F18: =IF(D18+E18=0," ",F17+D18-E18) | G18: =(F18-F5)/F5 -> #VALUE! | O18: =IF(L18+M18=0," ",O17+L18-M18) | X18: =IF(U18+V18=0," ",X17+U18-V18) | AG18: =IF(AD18+AE18=0," ",AG17+AD18-AE18)
O19: =IF(L19+M19=0," ",O18+L19-M19) | X19: =IF(U19+V19=0," ",X18+U19-V19) | AG19: =IF(AD19+AE19=0," ",AG18+AD19-AE19)
O20: =IF(L20+M20=0," ",O19+L20-M20) | X20: =IF(U20+V20=0," ",X19+U20-V20) | AG20: =IF(AD20+AE20=0," ",AG19+AD20-AE20)
O21: =IF(L21+M21=0," ",O20+L21-M21) | X21: =IF(U21+V21=0," ",X20+U21-V21) | AG21: =IF(AD21+AE21=0," ",AG20+AD21-AE21)
B22: Total | G22: =IFERROR(AVERAGE(G7:G21),0) -> 0 | O22: =IF(L22+M22=0," ",O21+L22-M22) | X22: =IF(U22+V22=0," ",X21+U22-V22) | AG22: =IF(AD22+AE22=0," ",AG21+AD22-AE22)
O23: =IF(L23+M23=0," ",O22+L23-M23) | X23: =IF(U23+V23=0," ",X22+U23-V23) | AG23: =IF(AD23+AE23=0," ",AG22+AD23-AE23)
O24: =IF(L24+M24=0," ",O23+L24-M24) | X24: =IF(U24+V24=0," ",X23+U24-V24) | AG24: =IF(AD24+AE24=0," ",AG23+AD24-AE24)
O25: =IF(L25+M25=0," ",O24+L25-M25) | X25: =IF(U25+V25=0," ",X24+U25-V25) | AG25: =IF(AD25+AE25=0," ",AG24+AD25-AE25)
O26: =IF(L26+M26=0," ",O25+L26-M26) | X26: =IF(U26+V26=0," ",X25+U26-V26) | AG26: =IF(AD26+AE26=0," ",AG25+AD26-AE26)
O27: =IF(L27+M27=0," ",O26+L27-M27) | X27: =IF(U27+V27=0," ",X26+U27-V27) | AG27: =IF(AD27+AE27=0," ",AG26+AD27-AE27)
O28: =IF(L28+M28=0," ",O27+L28-M28) | X28: =IF(U28+V28=0," ",X27+U28-V28) | AG28: =IF(AD28+AE28=0," ",AG27+AD28-AE28)
O29: =IF(L29+M29=0," ",O28+L29-M29) | X29: =IF(U29+V29=0," ",X28+U29-V29) | AG29: =IF(AD29+AE29=0," ",AG28+AD29-AE29)
O30: =IF(L30+M30=0," ",O29+L30-M30) | X30: =IF(U30+V30=0," ",X29+U30-V30) | AG30: =IF(AD30+AE30=0," ",AG29+AD30-AE30)
O31: =IF(L31+M31=0," ",O30+L31-M31) | X31: =IF(U31+V31=0," ",X30+U31-V31) | AG31: =IF(AD31+AE31=0," ",AG30+AD31-AE31)
O32: =IF(L32+M32=0," ",O31+L32-M32) | X32: =IF(U32+V32=0," ",X31+U32-V32) | AG32: =IF(AD32+AE32=0," ",AG31+AD32-AE32)
O33: =IF(L33+M33=0," ",O32+L33-M33) | X33: =IF(U33+V33=0," ",X32+U33-V33) | AG33: =IF(AD33+AE33=0," ",AG32+AD33-AE33)
O34: =IF(L34+M34=0," ",O33+L34-M34) | X34: =IF(U34+V34=0," ",X33+U34-V34) | AG34: =IF(AD34+AE34=0," ",AG33+AD34-AE34)
... O305: =IF(L305+M305=0," ",O304+L305-M305) | X305: =IF(U305+V305=0," ",X304+U305-V305) | AG305: =IF(AD305+AE305=0," ",AG304+AD305-AE305)

Sheet 💎MERCH💎
B1: Merchandising Detail
B2: Item | C2: P | D2: Q | E2: Total Gross | F2: COGS/Pcs | G2: Total COGS | H2: Net Profit
B3: Work Jacket | C3: 250000 | D3: 24 | E3: =C3*D3 -> 6000000 | G3: =F3*D3 -> 0 | H3: =E3-G3 -> 6000000
B4: Varsity | C4: 281000 | D4: 15 | E4: =C4*D4 -> 4215000 | G4: =F4*D4 -> 0 | H4: =E4-G4 -> 4215000
B5: Half Zip | C5: 225000 | D5: 15 | E5: =C5*D5 -> 3375000 | G5: =F5*D5 -> 0 | H5: =E5-G5 -> 3375000
B6: Kaos | C6: 85000 | D6: 30 | E6: =C6*D6 -> 2550000 | G6: =F6*D6 -> 0 | H6: =E6-G6 -> 2550000
B7: Topi | C7: 55000 | D7: 20 | E7: =C7*D7 -> 1100000 | G7: =F7*D7 -> 0 | H7: =E7-G7 -> 1100000
B8: Tumbler | C8: 75550 | D8: 20 | E8: =C8*D8 -> 1511000 | G8: =F8*D8 -> 0 | H8: =E8-G8 -> 1511000
B9: Totebag | C9: 50000 | D9: 40 | E9: =C9*D9 -> 2000000 | G9: =F9*D9 -> 0 | H9: =E9-G9 -> 2000000
B10: Keychain Biasa | C10: 20000 | D10: 140 | E10: =C10*D10 -> 2800000 | G10: =F10*D10 -> 0 | H10: =E10-G10 -> 2800000
B11: Keychain Clicker | C11: 50000 | D11: 10 | E11: =C11*D11 -> 500000 | G11: =F11*D11 -> 0 | H11: =E11-G11 -> 500000
B12: Sticker Pack | C12: 20000 | D12: 50 | E12: =C12*D12 -> 1000000 | G12: =F12*D12 -> 0 | H12: =E12-G12 -> 1000000
B13: Pin Tas 44 mm | C13: 3000 | D13: 100 | E13: =C13*D13 -> 300000 | G13: =F13*D13 -> 0 | H13: =E13-G13 -> 300000
B14: Pin Tas 58 mm | C14: 5000 | D14: 50 | E14: =C14*D14 -> 250000 | G14: =F14*D14 -> 0 | H14: =E14-G14 -> 250000
... B17: Bando Bara | C17: 15000 | D17: 50 | E17: =C17*D17 -> 750000 | G17: =F17*D17 -> 0 | H17: =E17-G17 -> 750000
B18: Pulpen | E18: =C18*D18 -> 0 | G18: =F18*D18 -> 0 | H18: =E18-G18 -> 0
B19: Pensil | E19: =C19*D19 -> 0 | G19: =F19*D19 -> 0 | H19: =E19-G19 -> 0
B20: Buku | E20: =C20*D20 -> 0 | G20: =F20*D20 -> 0 | H20: =E20-G20 -> 0
D21: =SUM(D2:D11) -> 314 | E21: =SUM(E3:E20) -> 35851000 | G21: =SUM(G3:G20) -> 0 | H21: =SUM(H3:H20) -> 35851000

Sheet TRACKING 💎MERCH💎
B1: 💎Merchandising Detail💎
B2: Item | C2: P | D2: Q | E2: Total Gross | F2: COGS/Pcs | G2: Total COGS | H2: Net Profit
B3: Work Jacket | C3: 250000 | D3: 24 | E3: =C3*D3 -> 6000000 | F3: 65000 | G3: =F3*D3 -> 1560000 | H3: =E3-G3 -> 4440000
B4: Varsity | C4: 281000 | D4: 15 | E4: =C4*D4 -> 4215000 | G4: =F4*D4 -> 0 | H4: =E4-G4 -> 4215000
B5: Half Zip | C5: 225000 | D5: 15 | E5: =C5*D5 -> 3375000 | G5: =F5*D5 -> 0 | H5: =E5-G5 -> 3375000
B6: Kaos | C6: 85000 | D6: 30 | E6: =C6*D6 -> 2550000 | G6: =F6*D6 -> 0 | H6: =E6-G6 -> 2550000
B7: Topi | C7: 55000 | D7: 20 | E7: =C7*D7 -> 1100000 | G7: =F7*D7 -> 0 | H7: =E7-G7 -> 1100000
B8: Tumbler | C8: 75550 | D8: 20 | E8: =C8*D8 -> 1511000 | G8: =F8*D8 -> 0 | H8: =E8-G8 -> 1511000
B9: Totebag | C9: 50000 | D9: 40 | E9: =C9*D9 -> 2000000 | G9: =F9*D9 -> 0 | H9: =E9-G9 -> 2000000
B10: Keychain Biasa | C10: 20000 | D10: 140 | E10: =C10*D10 -> 2800000 | G10: =F10*D10 -> 0 | H10: =E10-G10 -> 2800000
B11: Keychain Clicker | C11: 50000 | D11: 10 | E11: =C11*D11 -> 500000 | G11: =F11*D11 -> 0 | H11: =E11-G11 -> 500000
B12: Sticker Pack | C12: 20000 | D12: 50 | E12: =C12*D12 -> 1000000 | G12: =F12*D12 -> 0 | H12: =E12-G12 -> 1000000
B13: Pin Tas 44 mm | C13: 3000 | D13: 100 | E13: =C13*D13 -> 300000 | G13: =F13*D13 -> 0 | H13: =E13-G13 -> 300000
B14: Pin Tas 58 mm | C14: 5000 | D14: 50 | E14: =C14*D14 -> 250000 | G14: =F14*D14 -> 0 | H14: =E14-G14 -> 250000
B15: Pin Enamel | C15: 30000 | D15: 150 | E15: =C15*D15 -> 4500000 | G15: =F15*D15 -> 0 | H15: =E15-G15 -> 4500000
... B17: Bando Bara | C17: 15000 | D17: 50 | E17: =C17*D17 -> 750000 | G17: =F17*D17 -> 0 | H17: =E17-G17 -> 750000
B18: Pulpen | E18: =C18*D18 -> 0 | G18: =F18*D18 -> 0 | H18: =E18-G18 -> 0
B19: Pensil | E19: =C19*D19 -> 0 | G19: =F19*D19 -> 0 | H19: =E19-G19 -> 0
B20: Buku | E20: =C20*D20 -> 0 | G20: =F20*D20 -> 0 | H20: =E20-G20 -> 0
D21: =SUM(D3:D20) -> 814 | E21: =SUM(E3:E20) -> 35851000 | G21: =SUM(G3:G20) -> 1560000 | H21: =SUM(H3:H20) -> 34291000
B23: Total Quantity Based on Pre Order | F23: Ready stock to sell on-site
B24: Item | C24: Q | D24: Total | F24: Item | G24: Q | H24: Expected Profit
B25: Test | C25: =D3+D10 -> 164 | D25: =C25 -> 164
C26: =D4+D10 -> 155 | D26: =C26 -> 155
C27: =D5+D10+D11+D12 -> 215 | D27: =C27*4 -> 860
C28: =D6+D10+D11+D13 -> 280 | D28: =C28 -> 280
C29: =D7+D10+D11+D12+D13 -> 320 | D29: =ROUNDUP(C29/9+2,0) -> 38 | G29: =SUM(G25:G28) -> 0 | H29: =SUM(H25:H28) -> 0
C30: =D8+D14+D20 -> 70 | D30: =ROUNDUP(C30/9,0) + (5) -> 13
C31: =D9+D14+D20 -> 90 | D31: =C31 -> 90
C32: =#REF!+D14 -> #REF! | D32: =C32 -> #REF!
C33: =SUM(C24:C32) -> #REF! | D33: =SUM(D24:D32) -> #REF!
B35: 💎Production Costs💎
B36: Item | C36: Raw Materials Costs | D36: Detailed Quantity | E36: Q | F36: Total Q | G36: Direct Labor Costs | H36: COGS/Pcs | I36: Total COGS
B37: Work Jacket | D37: 1 | F37: =(D37*E37) -> 0 | G37: 0 | I37: =C37*E37+G37 -> 0
B38: Varsity | C38: 120000 | D38: 1 | E38: 20 | F38: =(D38*E38) -> 20 | G38: 30000 | H38: =I38/F38 -> 121500 | I38: =C38*E38+G38 -> 2430000
B39: Half Zip | D39: 1 | F39: =(D39*E39) -> 0 | G39: 0 | H39: =I39/F39 -> #DIV/0! | I39: =C39*E39+G39 -> 0
B40: Kaos | D40: 1 | E40: x | F40: =(D40*E40) -> #VALUE! | G40: 0 | H40: =I40/F40 -> #VALUE! | I40: =C40*E40+G40 -> #VALUE!
B41: Topi | D41: 1 | F41: =(D41*E41) -> 0 | G41: 0 | H41: =I41/F41 -> #DIV/0! | I41: =C41*E41+G41 -> 0
B42: Tumbler | D42: 1 | F42: =(D42*E42) -> 0 | G42: 0 | H42: =I42/F42 -> #DIV/0! | I42: =C42*E42+G42 -> 0
B43: Totebag | D43: 1 | F43: =(D43*E43) -> 0 | G43: 0 | H43: =I43/F43 -> #DIV/0! | I43: =C43*E43+G43 -> 0
...

Sheet Reimbursement
B1: Reimbursement Tracker
I3: =SUMIF($J$7:$J$597, "paid", $I$7:$I$597) -> 0 | J3: =COUNTIF($J$7:$J$597, "paid") -> 0
I4: =SUMIF($J$7:$J$597, "unpaid", I7:I597) -> 0 | J4: =COUNTIF($J$7:$J$597, "unpaid") -> 0
B6: Expense Proof | C6: Request Date | D6: Name | E6: Description | F6: Source | G6: Category | H6: Date Paid | I6: Amount of Money | J6: Status | K6: Proof link

Sheet READY STOCK MERCH
B1: 💎Merchandising Detail💎
B2: Item | C2: P | D2: Q | E2: Total Gross | F2: COGS/Pcs | G2: Total COGS | H2: Net Profit
E3: =C3*D3 -> 0 | G3: =F3*D3 -> 0 | H3: =E3-G3 -> 0
E4: =C4*D4 -> 0 | G4: =F4*D4 -> 0 | H4: =E4-G4 -> 0
E5: =C5*D5 -> 0 | G5: =F5*D5 -> 0 | H5: =E5-G5 -> 0
E6: =C6*D6 -> 0 | G6: =F6*D6 -> 0 | H6: =E6-G6 -> 0
E7: =C7*D7 -> 0 | G7: =F7*D7 -> 0 | H7: =E7-G7 -> 0
E8: =C8*D8 -> 0 | G8: =F8*D8 -> 0 | H8: =E8-G8 -> 0
D9: =SUM(D2:D8) -> 0 | E9: =SUM(E3:E8) -> 0 | G9: =SUM(G3:G8) -> 0 | H9: =SUM(H3:H8) -> 0

Sheet Sheet9
A1: Item ID | B1: Item name | C1: Type | D1: Initial Stock | E1: Stock In | F1: Sold (Qris Payment) | G1: Sold (Cash Payment) | H1: Remaining Stock | I1: Total Sold | J1: Unit Price | K1: Cost Price | L1: Revenue | M1: Profit | N1: Status | O1: Notes
A2: 1 | B2: Work Jacket | D2: 20 | F2: 6 | G2: 5 | H2: =(D2+E2) -(F2+G2) -> 9 | I2: =F2+G2 -> 11 | N2: In stock
A3: 2 | F3: 8 | H3: =(D3+E3) -(F3+G3) -> -8 | I3: =F3+G3 -> 8 | J3: 200000 | K3: 150000 | N3: Sold out
A4: 3 | E4: 68 | F4: 121 | H4: =(D4+E4) -(F4+G4) -> -53 | I4: =F4+G4 -> 121 | N4: In stock
A5: 4 | F5: 52 | H5: =(D5+E5) -(F5+G5) -> -52 | I5: =F5+G5 -> 52 | N5: In stock
A6: 5 | H6: =(D6+E6) -(F6+G6) -> 0 | I6: =F6+G6 -> 0 | N6: In stock
A7: 6 | F7: 3 | H7: =(D7+E7) -(F7+G7) -> -3 | I7: =F7+G7 -> 3 | N7: In stock
A8: 7 | F8: 4 | H8: =(D8+E8) -(F8+G8) -> -4 | I8: =F8+G8 -> 4 | N8: In stock
A9: 8 | F9: 2 | H9: =(D9+E9) -(F9+G9) -> -2 | I9: =F9+G9 -> 2 | N9: In stock
A10: 9 | F10: 7 | H10: =(D10+E10) -(F10+G10) -> -7 | I10: =F10+G10 -> 7 | N10: In stock
A11: 10 | F11: 35 | G11: 1 | H11: =(D11+E11) -(F11+G11) -> -36 | I11: =F11+G11 -> 36 | N11: In stock
A12: 11 | F12: 27 | G12: 5 | H12: =(D12+E12) -(F12+G12) -> -32 | I12: =F12+G12 -> 32 | N12: Re-purchase needed
A13: 12 | F13: 15 | H13: =(D13+E13) -(F13+G13) -> -15 | I13: =F13+G13 -> 15 | N13: In stock
A14: 13 | F14: 7 | H14: =(D14+E14) -(F14+G14) -> -7 | I14: =F14+G14 -> 7 | N14: In stock
A15: 14 | F15: 21 | H15: =(D15+E15) -(F15+G15) -> -21 | I15: =F15+G15 -> 21 | N15: Re-purchase needed
A16: 15 | F16: 6 | H16: =(D16+E16) -(F16+G16) -> -6 | I16: =F16+G16 -> 6 | N16: Sold out
A17: 16 | F17: 4 | H17: =(D17+E17) -(F17+G17) -> -4 | I17: =F17+G17 -> 4 | N17: In stock
A18: 17 | H18: =(D18+E18) -(F18+G18) -> 0 | I18: =F18+G18 -> 0
A19: 18 | H19: =(D19+E19) -(F19+G19) -> 0 | I19: =F19+G19 -> 0
A20: 19 | H20: =(D20+E20) -(F20+G20) -> 0 | I20: =F20+G20 -> 0
A21: 20 | H21: =(D21+E21) -(F21+G21) -> 0 | I21: =F21+G21 -> 0
A22: 21 | H22: =(D22+E22) -(F22+G22) -> 0 | I22: =F22+G22 -> 0
A23: 22 | H23: =(D23+E23) -(F23+G23) -> 0 | I23: =F23+G23 -> 0
A24: 23 | H24: =(D24+E24) -(F24+G24) -> 0 | I24: =F24+G24 -> 0
A25: 24 | H25: =(D25+E25) -(F25+G25) -> 0 | I25: =F25+G25 -> 0
A26: 25 | H26: =(D26+E26) -(F26+G26) -> 0 | I26: =F26+G26 -> 0
A27: 26 | H27: =(D27+E27) -(F27+G27) -> 0 | I27: =F27+G27 -> 0
A28: 27 | H28: =(D28+E28) -(F28+G28) -> 0 | I28: =F28+G28 -> 0
